Workbook
Name Slicer_Channel: #N/A
Name Slicer_CohortMonth: #N/A
Name Slicer_Country: #N/A
Name Slicer_ProductCategory: #N/A
Name Slicer_Region: #N/A
Name Slicer_Region1: #N/A
Name Slicer_Salesperson: #N/A
Name Slicer_SKU: #N/A
Name Slicer_Standardized_o_date1: #N/A

Sheet region hierachy
A3: Row Labels
A4: Africa
A5: Kenya
A6: Kisumu
A7: Mombasa
A8: Nairobi
A9: Nakuru
A10: Nigeria
A11: Abuja
A12: Lagos
A13: Port Harcourt
A14: unknown
... A68: Grand Total

Sheet cohort analysis
A3: Row Labels | B3: Sum of GrossRevenue
A4: Apr-2023 | B4: 371604.58
A5: Brazil | B5: 12248.676
A6: Canada | B6: 15618.845
A7: China | B7: 23379.011
A8: France | B8: 40811.052
A9: Germany | B9: 104633.05
A10: India | B10: 32506.559
A11: Japan | B11: 21196.913
A12: Kenya | B12: 11003.767
A13: Nigeria | B13: 32280.325
A14: United Kingdom | B14: 66551.125
A15: USA | B15: 11375.258
... A356: Grand Total | B356: 10928846

Sheet ABC pivot table
A3: ProductCategory | B3: SKU | C3: Sum of GrossRevenue
A4: Accessories | B4: ACC-1021 | C4: 1446.9507
A5: Accessories | B5: ACC-1028 | C5: 10693.885
A6: Accessories | B6: ACC-1060 | C6: 5610.0924
A7: Accessories | B7: ACC-1075 | C7: 10893.623
A8: Accessories | B8: ACC-1238 | C8: 17067.938
A9: Accessories | B9: ACC-1249 | C9: 14431.738
A10: Accessories | B10: ACC-1375 | C10: 31513.085
A11: Accessories | B11: ACC-1492 | C11: 7382.145
A12: Accessories | B12: ACC-1596 | C12: 7507.4515
A13: Accessories | B13: ACC-1604 | C13: 12040.644
A14: Accessories | B14: ACC-1659 | C14: 28386.016
A15: Accessories | B15: ACC-1663 | C15: 7578.84
... A91: Accessories | B91: ACC-9820 | C91: 549.8001
A92: Accessories Total | C92: 1331648.9
A93: Components | B93: CMP-1009 | C93: 6874.4829
A94: Components | B94: CMP-1072 | C94: 2316.2622
A95: Components | B95: CMP-1156 | C95: 33308.55
A96: Components | B96: CMP-1220 | C96: 15374.563
A97: Components | B97: CMP-1223 | C97: 6137.802
A98: Components | B98: CMP-1470 | C98: 2077.46
A99: Components | B99: CMP-1555 | C99: 13983.753
A100: Components | B100: CMP-1559 | C100: 27331.83
A101: Components | B101: CMP-1632 | C101: 97.0154
A102: Components | B102: CMP-1940 | C102: 40476.013
A103: Components | B103: CMP-2015 | C103: 16946.092
A104: Components | B104: CMP-2040 | C104: 65111.386
... A182: Components | B182: CMP-9801 | C182: 703.2428
A183: Components Total | C183: 1545647
A184: Laptops | B184: LAP-1066 | C184: 1009.2969
A185: Laptops | B185: LAP-1178 | C185: 41914.216
A186: Laptops | B186: LAP-1308 | C186: 42433.254
A187: Laptops | B187: LAP-1482 | C187: 14448.299
A188: Laptops | B188: LAP-1525 | C188: 12954.358
A189: Laptops | B189: LAP-1619 | C189: 20455.985
A190: Laptops | B190: LAP-1698 | C190: 7090.5672
A191: Laptops | B191: LAP-1739 | C191: 58526.831
A192: Laptops | B192: LAP-1946 | C192: 9771.4483
A193: Laptops | B193: LAP-1969 | C193: 3823.6152
A194: Laptops | B194: LAP-1989 | C194: 19581.87
...

Sheet ABC analysis by SKU
A1: ProductCategory | B1: SKU | C1: Sum of GrossRevenue | D1: Revenue_% | E1: Cumulative_% | F1: ABC_Classification
A2: Accessories | B2: ACC-1021 | C2: 1446.9507 | D2: =C2/SUMIFS($C:$C,$A:$A,A2) -> 0.0010865857 | E2: =SUMIFS($D$2:D2,$A$2:A2,A2) -> 0.0010865857 | F2: =IF(E2<=0.8,"A",IF(E2<=0.95,"B","C")) -> A
A3: Accessories | B3: ACC-1028 | C3: 10693.885 | D3: =C3/SUMIFS($C:$C,$A:$A,A3) -> 0.0080305588 | E3: =SUMIFS($D$2:D3,$A$2:A3,A3) -> 0.0091171445 | F3: =IF(E3<=0.8,"A",IF(E3<=0.95,"B","C")) -> A
A4: Accessories | B4: ACC-1060 | C4: 5610.0924 | D4: =C4/SUMIFS($C:$C,$A:$A,A4) -> 0.0042128915 | E4: =SUMIFS($D$2:D4,$A$2:A4,A4) -> 0.013330036 | F4: =IF(E4<=0.8,"A",IF(E4<=0.95,"B","C")) -> A
A5: Accessories | B5: ACC-1075 | C5: 10893.623 | D5: =C5/SUMIFS($C:$C,$A:$A,A5) -> 0.008180552 | E5: =SUMIFS($D$2:D5,$A$2:A5,A5) -> 0.021510588 | F5: =IF(E5<=0.8,"A",IF(E5<=0.95,"B","C")) -> A
A6: Accessories | B6: ACC-1238 | C6: 17067.938 | D6: =C6/SUMIFS($C:$C,$A:$A,A6) -> 0.012817146 | E6: =SUMIFS($D$2:D6,$A$2:A6,A6) -> 0.034327734 | F6: =IF(E6<=0.8,"A",IF(E6<=0.95,"B","C")) -> A
A7: Accessories | B7: ACC-1249 | C7: 14431.738 | D7: =C7/SUMIFS($C:$C,$A:$A,A7) -> 0.010837495 | E7: =SUMIFS($D$2:D7,$A$2:A7,A7) -> 0.045165229 | F7: =IF(E7<=0.8,"A",IF(E7<=0.95,"B","C")) -> A
A8: Accessories | B8: ACC-1375 | C8: 31513.085 | D8: =C8/SUMIFS($C:$C,$A:$A,A8) -> 0.02366471 | E8: =SUMIFS($D$2:D8,$A$2:A8,A8) -> 0.068829939 | F8: =IF(E8<=0.8,"A",IF(E8<=0.95,"B","C")) -> A
A9: Accessories | B9: ACC-1492 | C9: 7382.145 | D9: =C9/SUMIFS($C:$C,$A:$A,A9) -> 0.0055436121 | E9: =SUMIFS($D$2:D9,$A$2:A9,A9) -> 0.074373551 | F9: =IF(E9<=0.8,"A",IF(E9<=0.95,"B","C")) -> A
A10: Accessories | B10: ACC-1596 | C10: 7507.4515 | D10: =C10/SUMIFS($C:$C,$A:$A,A10) -> 0.0056377108 | E10: =SUMIFS($D$2:D10,$A$2:A10,A10) -> 0.080011261 | F10: =IF(E10<=0.8,"A",IF(E10<=0.95,"B","C")) -> A
A11: Accessories | B11: ACC-1604 | C11: 12040.644 | D11: =C11/SUMIFS($C:$C,$A:$A,A11) -> 0.0090419054 | E11: =SUMIFS($D$2:D11,$A$2:A11,A11) -> 0.089053167 | F11: =IF(E11<=0.8,"A",IF(E11<=0.95,"B","C")) -> A
A12: Accessories | B12: ACC-1659 | C12: 28386.016 | D12: =C12/SUMIFS($C:$C,$A:$A,A12) -> 0.021316441 | E12: =SUMIFS($D$2:D12,$A$2:A12,A12) -> 0.11036961 | F12: =IF(E12<=0.8,"A",IF(E12<=0.95,"B","C")) -> A
A13: Accessories | B13: ACC-1663 | C13: 7578.84 | D13: =C13/SUMIFS($C:$C,$A:$A,A13) -> 0.0056913199 | E13: =SUMIFS($D$2:D13,$A$2:A13,A13) -> 0.11606093 | F13: =IF(E13<=0.8,"A",IF(E13<=0.95,"B","C")) -> A
... A89: Accessories | B89: ACC-9820 | C89: 549.8001 | D89: =C89/SUMIFS($C:$C,$A:$A,A89) -> 0.00041287166 | E89: =SUMIFS($D$2:D89,$A$2:A89,A89) -> 1 | F89: =IF(E89<=0.8,"A",IF(E89<=0.95,"B","C")) -> C
A90: Accessories Total | C90: 1331648.9 | D90: =C90/SUMIFS($C:$C,$A:$A,A90) -> 1 | E90: =SUMIFS($D$2:D90,$A$2:A90,A90) -> 1 | F90: =IF(E90<=0.8,"A",IF(E90<=0.95,"B","C")) -> C
A91: Components | B91: CMP-1009 | C91: 6874.4829 | D91: =C91/SUMIFS($C:$C,$A:$A,A91) -> 0.0044476409 | E91: =SUMIFS($D$2:D91,$A$2:A91,A91) -> 0.0044476409 | F91: =IF(E91<=0.8,"A",IF(E91<=0.95,"B","C")) -> A
A92: Components | B92: CMP-1072 | C92: 2316.2622 | D92: =C92/SUMIFS($C:$C,$A:$A,A92) -> 0.0014985713 | E92: =SUMIFS($D$2:D92,$A$2:A92,A92) -> 0.0059462122 | F92: =IF(E92<=0.8,"A",IF(E92<=0.95,"B","C")) -> A
A93: Components | B93: CMP-1156 | C93: 33308.55 | D93: =C93/SUMIFS($C:$C,$A:$A,A93) -> 0.021549908 | E93: =SUMIFS($D$2:D93,$A$2:A93,A93) -> 0.02749612 | F93: =IF(E93<=0.8,"A",IF(E93<=0.95,"B","C")) -> A
A94: Components | B94: CMP-1220 | C94: 15374.563 | D94: =C94/SUMIFS($C:$C,$A:$A,A94) -> 0.0099470081 | E94: =SUMIFS($D$2:D94,$A$2:A94,A94) -> 0.037443128 | F94: =IF(E94<=0.8,"A",IF(E94<=0.95,"B","C")) -> A
A95: Components | B95: CMP-1223 | C95: 6137.802 | D95: =C95/SUMIFS($C:$C,$A:$A,A95) -> 0.0039710244 | E95: =SUMIFS($D$2:D95,$A$2:A95,A95) -> 0.041414152 | F95: =IF(E95<=0.8,"A",IF(E95<=0.95,"B","C")) -> A
A96: Components | B96: CMP-1470 | C96: 2077.46 | D96: =C96/SUMIFS($C:$C,$A:$A,A96) -> 0.0013440714 | E96: =SUMIFS($D$2:D96,$A$2:A96,A96) -> 0.042758224 | F96: =IF(E96<=0.8,"A",IF(E96<=0.95,"B","C")) -> A
A97: Components | B97: CMP-1555 | C97: 13983.753 | D97: =C97/SUMIFS($C:$C,$A:$A,A97) -> 0.009047184 | E97: =SUMIFS($D$2:D97,$A$2:A97,A97) -> 0.051805408 | F97: =IF(E97<=0.8,"A",IF(E97<=0.95,"B","C")) -> A
A98: Components | B98: CMP-1559 | C98: 27331.83 | D98: =C98/SUMIFS($C:$C,$A:$A,A98) -> 0.0176831 | E98: =SUMIFS($D$2:D98,$A$2:A98,A98) -> 0.069488508 | F98: =IF(E98<=0.8,"A",IF(E98<=0.95,"B","C")) -> A
A99: Components | B99: CMP-1632 | C99: 97.0154 | D99: =C99/SUMIFS($C:$C,$A:$A,A99) -> 6.2766854e-05 | E99: =SUMIFS($D$2:D99,$A$2:A99,A99) -> 0.069551274 | F99: =IF(E99<=0.8,"A",IF(E99<=0.95,"B","C")) -> A
A100: Components | B100: CMP-1940 | C100: 40476.013 | D100: =C100/SUMIFS($C:$C,$A:$A,A100) -> 0.0261871 | E100: =SUMIFS($D$2:D100,$A$2:A100,A100) -> 0.095738375 | F100: =IF(E100<=0.8,"A",IF(E100<=0.95,"B","C")) -> A
A101: Components | B101: CMP-2015 | C101: 16946.092 | D101: =C101/SUMIFS($C:$C,$A:$A,A101) -> 0.010963753 | E101: =SUMIFS($D$2:D101,$A$2:A101,A101) -> 0.10670213 | F101: =IF(E101<=0.8,"A",IF(E101<=0.95,"B","C")) -> A
A102: Components | B102: CMP-2040 | C102: 65111.386 | D102: =C102/SUMIFS($C:$C,$A:$A,A102) -> 0.042125651 | E102: =SUMIFS($D$2:D102,$A$2:A102,A102) -> 0.14882778 | F102: =IF(E102<=0.8,"A",IF(E102<=0.95,"B","C")) -> A
... A180: Components | B180: CMP-9801 | C180: 703.2428 | D180: =C180/SUMIFS($C:$C,$A:$A,A180) -> 0.0004549828 | E180: =SUMIFS($D$2:D180,$A$2:A180,A180) -> 1 | F180: =IF(E180<=0.8,"A",IF(E180<=0.95,"B","C")) -> C
A181: Components Total | C181: 1545647 | D181: =C181/SUMIFS($C:$C,$A:$A,A181) -> 1 | E181: =SUMIFS($D$2:D181,$A$2:A181,A181) -> 1 | F181: =IF(E181<=0.8,"A",IF(E181<=0.95,"B","C")) -> C
A182: Laptops | B182: LAP-1066 | C182: 1009.2969 | D182: =C182/SUMIFS($C:$C,$A:$A,A182) -> 0.00058985461 | E182: =SUMIFS($D$2:D182,$A$2:A182,A182) -> 0.00058985461 | F182: =IF(E182<=0.8,"A",IF(E182<=0.95,"B","C")) -> A
A183: Laptops | B183: LAP-1178 | C183: 41914.216 | D183: =C183/SUMIFS($C:$C,$A:$A,A183) -> 0.02449556 | E183: =SUMIFS($D$2:D183,$A$2:A183,A183) -> 0.025085415 | F183: =IF(E183<=0.8,"A",IF(E183<=0.95,"B","C")) -> A
A184: Laptops | B184: LAP-1308 | C184: 42433.254 | D184: =C184/SUMIFS($C:$C,$A:$A,A184) -> 0.024798898 | E184: =SUMIFS($D$2:D184,$A$2:A184,A184) -> 0.049884313 | F184: =IF(E184<=0.8,"A",IF(E184<=0.95,"B","C")) -> A
A185: Laptops | B185: LAP-1482 | C185: 14448.299 | D185: =C185/SUMIFS($C:$C,$A:$A,A185) -> 0.0084438935 | E185: =SUMIFS($D$2:D185,$A$2:A185,A185) -> 0.058328206 | F185: =IF(E185<=0.8,"A",IF(E185<=0.95,"B","C")) -> A
A186: Laptops | B186: LAP-1525 | C186: 12954.358 | D186: =C186/SUMIFS($C:$C,$A:$A,A186) -> 0.0075708028 | E186: =SUMIFS($D$2:D186,$A$2:A186,A186) -> 0.065899009 | F186: =IF(E186<=0.8,"A",IF(E186<=0.95,"B","C")) -> A
A187: Laptops | B187: LAP-1619 | C187: 20455.985 | D187: =C187/SUMIFS($C:$C,$A:$A,A187) -> 0.011954913 | E187: =SUMIFS($D$2:D187,$A$2:A187,A187) -> 0.077853922 | F187: =IF(E187<=0.8,"A",IF(E187<=0.95,"B","C")) -> A
A188: Laptops | B188: LAP-1698 | C188: 7090.5672 | D188: =C188/SUMIFS($C:$C,$A:$A,A188) -> 0.0041438785 | E188: =SUMIFS($D$2:D188,$A$2:A188,A188) -> 0.081997801 | F188: =IF(E188<=0.8,"A",IF(E188<=0.95,"B","C")) -> A
A189: Laptops | B189: LAP-1739 | C189: 58526.831 | D189: =C189/SUMIFS($C:$C,$A:$A,A189) -> 0.034204327 | E189: =SUMIFS($D$2:D189,$A$2:A189,A189) -> 0.11620213 | F189: =IF(E189<=0.8,"A",IF(E189<=0.95,"B","C")) -> A
A190: Laptops | B190: LAP-1946 | C190: 9771.4483 | D190: =C190/SUMIFS($C:$C,$A:$A,A190) -> 0.0057106425 | E190: =SUMIFS($D$2:D190,$A$2:A190,A190) -> 0.12191277 | F190: =IF(E190<=0.8,"A",IF(E190<=0.95,"B","C")) -> A
A191: Laptops | B191: LAP-1969 | C191: 3823.6152 | D191: =C191/SUMIFS($C:$C,$A:$A,A191) -> 0.0022346021 | E191: =SUMIFS($D$2:D191,$A$2:A191,A191) -> 0.12414737 | F191: =IF(E191<=0.8,"A",IF(E191<=0.95,"B","C")) -> A
A192: Laptops | B192: LAP-1989 | C192: 19581.87 | D192: =C192/SUMIFS($C:$C,$A:$A,A192) -> 0.011444062 | E192: =SUMIFS($D$2:D192,$A$2:A192,A192) -> 0.13559143 | F192: =IF(E192<=0.8,"A",IF(E192<=0.95,"B","C")) -> A
...

Sheet salesperson pivot_table
A3: Row Labels | B3: Count of OrderID | C3: Sum of GrossRevenue | D3: Sum of GrossProfit
A4: A. Patel | B4: 46 | C4: 877159.52 | D4: 281944.47
A5: B. Chen | B5: 48 | C5: 893735.66 | D5: 315969.97
A6: C. Otieno | B6: 37 | C6: 685111.86 | D6: 225695.02
A7: D. Smith | B7: 38 | C7: 576820.19 | D7: 151076.93
A8: E. Garcia | B8: 34 | C8: 543846.44 | D8: 204981.34
A9: F. Müller | B9: 51 | C9: 812637.17 | D9: 251733.01
A10: G. Dubois | B10: 30 | C10: 510653.71 | D10: 172441.87
A11: H. Kim | B11: 45 | C11: 697568.3 | D11: 137020.81
A12: I. Johnson | B12: 38 | C12: 541165.67 | D12: 140021.69
A13: J. Njeri | B13: 50 | C13: 802384.66 | D13: 273113.11
A14: K. Singh | B14: 44 | C14: 883348.13 | D14: 278762.27
A15: L. Okafor | B15: 46 | C15: 853038.52 | D15: 269716.55
... A20: Grand Total | B20: 632 | C20: 10928846 | D20: 3401098

Sheet Salesperson_productivity
A1: Row Labels | B1: Count of OrderID | C1: Sum of GrossRevenue | D1: Sum of GrossProfit | E1: Revenue/Order | F1: Order/month | G1: Profit/Order
A2: A. Patel | B2: 46 | C2: 877159.52 | D2: 281944.47 | E2: =C2/B2 -> 19068.685 | F2: =B2/33 -> 1.3939394 | G2: =D2/B2 -> 6129.2276
A3: B. Chen | B3: 48 | C3: 893735.66 | D3: 315969.97 | E3: =C3/B3 -> 18619.493 | F3: =B3/33 -> 1.4545455 | G3: =D3/B3 -> 6582.7077 | I3: Yellow---bottom 3
A4: C. Otieno | B4: 37 | C4: 685111.86 | D4: 225695.02 | E4: =C4/B4 -> 18516.537 | F4: =B4/33 -> 1.1212121 | G4: =D4/B4 -> 6099.8654 | I4: Red ---- top 3
A5: D. Smith | B5: 38 | C5: 576820.19 | D5: 151076.93 | E5: =C5/B5 -> 15179.479 | F5: =B5/33 -> 1.1515152 | G5: =D5/B5 -> 3975.7087
A6: E. Garcia | B6: 34 | C6: 543846.44 | D6: 204981.34 | E6: =C6/B6 -> 15995.484 | F6: =B6/33 -> 1.030303 | G6: =D6/B6 -> 6028.863
A7: F. Müller | B7: 51 | C7: 812637.17 | D7: 251733.01 | E7: =C7/B7 -> 15934.062 | F7: =B7/33 -> 1.5454545 | G7: =D7/B7 -> 4935.9414
A8: G. Dubois | B8: 30 | C8: 510653.71 | D8: 172441.87 | E8: =C8/B8 -> 17021.79 | F8: =B8/33 -> 0.90909091 | G8: =D8/B8 -> 5748.0624
A9: H. Kim | B9: 45 | C9: 697568.3 | D9: 137020.81 | E9: =C9/B9 -> 15501.518 | F9: =B9/33 -> 1.3636364 | G9: =D9/B9 -> 3044.9069
A10: I. Johnson | B10: 38 | C10: 541165.67 | D10: 140021.69 | E10: =C10/B10 -> 14241.202 | F10: =B10/33 -> 1.1515152 | G10: =D10/B10 -> 3684.7814
A11: J. Njeri | B11: 50 | C11: 802384.66 | D11: 273113.11 | E11: =C11/B11 -> 16047.693 | F11: =B11/33 -> 1.5151515 | G11: =D11/B11 -> 5462.2622
A12: K. Singh | B12: 44 | C12: 883348.13 | D12: 278762.27 | E12: =C12/B12 -> 20076.094 | F12: =B12/33 -> 1.3333333 | G12: =D12/B12 -> 6335.5061
A13: L. Okafor | B13: 46 | C13: 853038.52 | D13: 269716.55 | E13: =C13/B13 -> 18544.316 | F13: =B13/33 -> 1.3939394 | G13: =D13/B13 -> 5863.4033
A14: M. Rossi | B14: 48 | C14: 966298.99 | D14: 302657.06 | E14: =C14/B14 -> 20131.229 | F14: =B14/33 -> 1.4545455 | G14: =D14/B14 -> 6305.3554
A15: N. Brown | B15: 32 | C15: 388325.14 | D15: 110646.46 | E15: =C15/B15 -> 12135.161 | F15: =B15/33 -> 0.96969697 | G15: =D15/B15 -> 3457.7018
A16: O. Wang | B16: 37 | C16: 647724.9 | D16: 185219.44 | E16: =C16/B16 -> 17506.078 | F16: =B16/33 -> 1.1212121 | G16: =D16/B16 -> 5005.9307
A17: unknown | B17: 8 | C17: 249026.85 | D17: 100098 | E17: =C17/B17 -> 31128.356 | F17: =B17/33 -> 0.24242424 | G17: =D17/B17 -> 12512.25

Sheet Cannibalization
A3: Sum of GrossRevenue | B3: Column Labels
A4: Row Labels | B4: Direct | C4: Distributor | D4: Marketplace | E4: Online | F4: Retail | G4: unknown | H4: Grand Total
A5: Africa | B5: 0.1776342 | C5: 0.24017767 | D5: 0.2030569 | E5: 0.16684646 | F5: 0.1996899 | G5: 0.012594885 | H5: 1
A6: Americas | B6: 0.27964209 | C6: 0.21140873 | D6: 0.13626255 | E6: 0.25660677 | F6: 0.11263731 | G6: 0.0034425439 | H6: 1
A7: Asia | B7: 0.22609014 | C7: 0.1792799 | D7: 0.19054974 | E7: 0.14558001 | F7: 0.24393754 | G7: 0.014562662 | H7: 1
A8: Europe | B8: 0.30082759 | C8: 0.11379438 | D8: 0.20338414 | E8: 0.20900009 | F8: 0.16654949 | G8: 0.0064443142 | H8: 1
A9: Grand Total | B9: 0.24690255 | C9: 0.18487541 | D9: 0.18345598 | E9: 0.19420404 | F9: 0.18128356 | G9: 0.0092784644 | H9: 1

Sheet Price compliance
A3: Row Labels | B3: Average of DiscountFlag | C3: FLAGS
A4: A. Patel | B4: 0.19565217 | C4: =IF(B4>30%,"OUTLIER","OK") -> OK
A5: Africa | B5: 0.1875 | C5: =IF(B5>30%,"OUTLIER","OK") -> OK
A6: Americas | B6: 0.5 | C6: =IF(B6>30%,"OUTLIER","OK") -> OUTLIER
A7: Asia | B7: 0 | C7: =IF(B7>30%,"OUTLIER","OK") -> OK
A8: Europe | B8: 0.1 | C8: =IF(B8>30%,"OUTLIER","OK") -> OK
A9: B. Chen | B9: 0.10416667 | C9: =IF(B9>30%,"OUTLIER","OK") -> OK
A10: Africa | B10: 0 | C10: =IF(B10>30%,"OUTLIER","OK") -> OK
A11: Americas | B11: 0.125 | C11: =IF(B11>30%,"OUTLIER","OK") -> OK
A12: Asia | B12: 0.11764706 | C12: =IF(B12>30%,"OUTLIER","OK") -> OK
A13: Europe | B13: 0.13333333 | C13: =IF(B13>30%,"OUTLIER","OK") -> OK
A14: C. Otieno | B14: 0.21621622 | C14: =IF(B14>30%,"OUTLIER","OK") -> OK
A15: Africa | B15: 0.25 | C15: =IF(B15>30%,"OUTLIER","OK") -> OK
... A84: Grand Total | B84: 0.14240506 | C84: =IF(B84>30%,"OUTLIER","OK") -> OK

Sheet Box and whisker chart
A1: Row Labels | B1: Africa | C1: Americas | D1: Asia | E1: Europe | F1: Grand Total
A2: A. Patel | B2: 0.1875 | C2: 0.5 | D2: 0 | E2: 0.1 | F2: 0.19565217
A3: B. Chen | B3: 0 | C3: 0.125 | D3: 0.11764706 | E3: 0.13333333 | F3: 0.10416667
A4: C. Otieno | B4: 0.25 | C4: 0.14285714 | D4: 0.3 | E4: 0.2 | F4: 0.21621622
A5: D. Smith | B5: 0.2 | C5: 0.5 | D5: 0.11111111 | E5: 0.090909091 | F5: 0.21052632
A6: E. Garcia | B6: 0.2 | C6: 0 | D6: 0 | E6: 0.125 | F6: 0.088235294
A7: F. Müller | B7: 0 | C7: 0.066666667 | D7: 0.25 | E7: 0 | F7: 0.078431373
A8: G. Dubois | B8: 0 | C8: 0.125 | D8: 0.090909091 | E8: 0.125 | F8: 0.1
A9: H. Kim | B9: 0.14285714 | C9: 0 | D9: 0.125 | E9: 0.076923077 | F9: 0.088888889
A10: I. Johnson | B10: 0.25 | C10: 0.35714286 | D10: 0.125 | E10: 0.125 | F10: 0.23684211
A11: J. Njeri | B11: 0.25 | C11: 0 | D11: 0.10526316 | E11: 0.11111111 | F11: 0.12
A12: K. Singh | B12: 0 | C12: 0.1 | D12: 0.14285714 | E12: 0.15384615 | F12: 0.090909091
A13: L. Okafor | B13: 0.2 | C13: 0.25 | D13: 0.21428571 | E13: 0 | F13: 0.17391304
... A17: unknown | B17: 0.5 | C17: 0.33333333 | D17: 0 | E17: 0 | F17: 0.25

Sheet Scenario Summary 2
B2: Scenario Summary
D3: Current Values: | E3: Scenario1 | F3: Scenario2
E4: Created by Admin on 6/20/2026 | F4: Created by Admin on 6/20/2026
B5: Changing Cells:
C6: $B$2 | D6: 0.2 | E6: 0.2 | F6: 0.1
C7: $B$3 | D7: 0.05 | E7: 0.05 | F7: 0.1
C8: $B$4 | D8: 0.1 | E8: 0.1 | F8: 0.5
B9: Result Cells:
C10: $J$7 | D10: 2450.2619 | E10: 2450.2619 | F10: 3251.421
B11: Notes: Current Values column represents values of changing cells at
B12: time Scenario Summary Report was created. Changing cells for each
B13: scenario are highlighted in gray.

Sheet Scenario Model
A1: INPUTS
A2: Discount Cap | B2: 0.2
A3: Cost Inflation | B3: 0.05
A4: Quantity Uplift | B4: 0.1
A6: OrderId | B6: Unitcost | C6: Unitprice | D6: Discountpct | E6: Quantity | F6: ScenarioDiscount | G6: ScenarioUnitCost | H6: ScenarioQty | I6: ScenarioRevenue | J6: ScenarioProfit | K6: ScenarioCOGS
A7: =Original!A2 -> ORD-2024-275203 | B7: =Original!R2 -> 279.24 | C7: =Original!S2 -> 608.9 | D7: =Original!T2 -> 0.112 | E7: =Original!V2 -> 9 | F7: =MIN(D7,$B$2) -> 0.112 | G7: =B7*(1+$B$3) -> 293.202 | H7: =E7*(1+$B$4) -> 9.9 | I7: =C7*H7*(1-F7) -> 5352.9617 | J7: =I7-K7 -> 2450.2619 | K7: =G7*H7 -> 2902.6998
A8: =Original!A3 -> ORD-2024-358795 | B8: =Original!R3 -> 1084.39 | C8: =Original!S3 -> 759.33 | D8: =Original!T3 -> 0.237 | E8: =Original!V3 -> 31 | F8: =MIN(D8,$B$2) -> 0.2 | G8: =B8*(1+$B$3) -> 1138.6095 | H8: =E8*(1+$B$4) -> 34.1 | I8: =C8*H8*(1-F8) -> 20714.522 | J8: =I8-K8 -> -18112.062 | K8: =G8*H8 -> 38826.584
A9: =Original!A4 -> ORD-2023-373538 | B9: =Original!R4 -> 1460.76 | C9: =Original!S4 -> 30.66 | D9: =Original!T4 -> 0.131 | E9: =Original!V4 -> 12 | F9: =MIN(D9,$B$2) -> 0.131 | G9: =B9*(1+$B$3) -> 1533.798 | H9: =E9*(1+$B$4) -> 13.2 | I9: =C9*H9*(1-F9) -> 351.69473 | J9: =I9-K9 -> -19894.439 | K9: =G9*H9 -> 20246.134
A10: =Original!A5 -> ORD-2025-168148 | B10: =Original!R5 -> 259.93 | C10: =Original!S5 -> 255.94 | D10: =Original!T5 -> 0.072 | E10: =Original!V5 -> 22 | F10: =MIN(D10,$B$2) -> 0.072 | G10: =B10*(1+$B$3) -> 272.9265 | H10: =E10*(1+$B$4) -> 24.2 | I10: =C10*H10*(1-F10) -> 5747.7981 | J10: =I10-K10 -> -857.02316 | K10: =G10*H10 -> 6604.8213
A11: =Original!A6 -> ORD-2023-824839 | B11: =Original!R6 -> 663.03 | C11: =Original!S6 -> 813.51 | D11: =Original!T6 -> 0.102 | E11: =Original!V6 -> 15 | F11: =MIN(D11,$B$2) -> 0.102 | G11: =B11*(1+$B$3) -> 696.1815 | H11: =E11*(1+$B$4) -> 16.5 | I11: =C11*H11*(1-F11) -> 12053.778 | J11: =I11-K11 -> 566.78292 | K11: =G11*H11 -> 11486.995
A12: =Original!A7 -> ORD-2023-723587 | B12: =Original!R7 -> 315.87 | C12: =Original!S7 -> 591.68 | D12: =Original!T7 -> 0 | E12: =Original!V7 -> 7 | F12: =MIN(D12,$B$2) -> 0 | G12: =B12*(1+$B$3) -> 331.6635 | H12: =E12*(1+$B$4) -> 7.7 | I12: =C12*H12*(1-F12) -> 4555.936 | J12: =I12-K12 -> 2002.1271 | K12: =G12*H12 -> 2553.809
A13: =Original!A8 -> ORD-2024-336584 | B13: =Original!R8 -> 586.07 | C13: =Original!S8 -> 845.97 | D13: =Original!T8 -> 0.147 | E13: =Original!V8 -> 4 | F13: =MIN(D13,$B$2) -> 0.147 | G13: =B13*(1+$B$3) -> 615.3735 | H13: =E13*(1+$B$4) -> 4.4 | I13: =C13*H13*(1-F13) -> 3175.0946 | J13: =I13-K13 -> 467.4512 | K13: =G13*H13 -> 2707.6434
A14: =Original!A9 -> ORD-2023-112666 | B14: =Original!R9 -> 28.38 | C14: =Original!S9 -> 47.22 | D14: =Original!T9 -> 0.194 | E14: =Original!V9 -> 18 | F14: =MIN(D14,$B$2) -> 0.194 | G14: =B14*(1+$B$3) -> 29.799 | H14: =E14*(1+$B$4) -> 19.8 | I14: =C14*H14*(1-F14) -> 753.57454 | J14: =I14-K14 -> 163.55434 | K14: =G14*H14 -> 590.0202
A15: =Original!A10 -> ORD-2024-589570 | B15: =Original!R10 -> 1295.34 | C15: =Original!S10 -> 2530.81 | D15: =Original!T10 -> 0.031 | E15: =Original!V10 -> 6 | F15: =MIN(D15,$B$2) -> 0.031 | G15: =B15*(1+$B$3) -> 1360.107 | H15: =E15*(1+$B$4) -> 6.6 | I15: =C15*H15*(1-F15) -> 16185.542 | J15: =I15-K15 -> 7208.8361 | K15: =G15*H15 -> 8976.7062
A16: =Original!A11 -> ORD-2025-997421 | B16: =Original!R11 -> 1331.38 | C16: =Original!S11 -> 2309.56 | D16: =Original!T11 -> 0.149 | E16: =Original!V11 -> 31 | F16: =MIN(D16,$B$2) -> 0.149 | G16: =B16*(1+$B$3) -> 1397.949 | H16: =E16*(1+$B$4) -> 34.1 | I16: =C16*H16*(1-F16) -> 67021.353 | J16: =I16-K16 -> 19351.292 | K16: =G16*H16 -> 47670.061
A17: =Original!A12 -> ORD-2024-210687 | B17: =Original!R12 -> 644.17 | C17: =Original!S12 -> 700.12 | D17: =Original!T12 -> 0.006 | E17: =Original!V12 -> 23 | F17: =MIN(D17,$B$2) -> 0.006 | G17: =B17*(1+$B$3) -> 676.3785 | H17: =E17*(1+$B$4) -> 25.3 | I17: =C17*H17*(1-F17) -> 17606.758 | J17: =I17-K17 -> 494.38173 | K17: =G17*H17 -> 17112.376
A18: =Original!A13 -> ORD-2025-515515 | B18: =Original!R13 -> 908.6 | C18: =Original!S13 -> 691.37 | D18: =Original!T13 -> 0.25 | E18: =Original!V13 -> 20 | F18: =MIN(D18,$B$2) -> 0.2 | G18: =B18*(1+$B$3) -> 954.03 | H18: =E18*(1+$B$4) -> 22 | I18: =C18*H18*(1-F18) -> 12168.112 | J18: =I18-K18 -> -8820.548 | K18: =G18*H18 -> 20988.66
... A638: =Original!A633 -> ORD-2025-728935 | B638: =Original!R633 -> 51.86 | C638: =Original!S633 -> 45.98 | D638: =Original!T633 -> 0.173 | E638: =Original!V633 -> 7 | F638: =MIN(D638,$B$2) -> 0.173 | G638: =B638*(1+$B$3) -> 54.453 | H638: =E638*(1+$B$4) -> 7.7 | I638: =C638*H638*(1-F638) -> 292.79604 | J638: =I638-K638 -> -126.49206 | K638: =G638*H638 -> 419.2881

Sheet Scenario Summary
B2: Scenario Summary
D3: Current Values: | E3: conservative | F3: expected | G3: aggressive growth
E4: Created by User on 19/06/2026 Modified by User on 19/06/2026 | F4: Created by User on 19/06/2026 Modified by User on 19/06/2026 | G4: Created by User on 19/06/2026
B5: Changing Cells:
C6: $B$1 | D6: 0.2 | E6: 0.1 | F6: 0.15 | G6: 0.2
C7: $B$2 | D7: 0.05 | E7: 0.1 | F7: 0.05 | G7: 0
C8: $B$3 | D8: 0.1 | E8: 0 | F8: 0.1 | G8: 0.2
B10: Notes: Current Values column represents values of changing cells at
B11: time Scenario Summary Report was created. Changing cells for each
B12: scenario are highlighted in gray.

Sheet data table what-if 
A1: Discount Cap | B1: 0.2
A2: Cost Inflation | B2: 0.05
A3: Quantity Uplift | B3: 0.1
D6: Discount cap
C7: =J31 -> 18046.859 | D7: 0 | E7: 0.05 | F7: 0.1 | G7: 0.15 | H7: 0.2
B8: quantity uplift | C8: 0 | D8: 19975.663 | E8: 19975.663 | F8: 19975.663 | G8: 19975.663 | H8: 19975.663
C9: 0.05 | D9: 19011.261 | E9: 19011.261 | F9: 19011.261 | G9: 19011.261 | H9: 19011.261
C10: 0.1 | D10: 18046.859 | E10: 18046.859 | F10: 18046.859 | G10: 18046.859 | H10: 18046.859
C11: 0.15 | D11: 17082.457 | E11: 17082.457 | F11: 17082.457 | G11: 17082.457 | H11: 17082.457
C12: 0.2 | D12: 16118.055 | E12: 16118.055 | F12: 16118.055 | G12: 16118.055 | H12: 16118.055
A30: OrderId | B30: Unitcost | C30: Unitprice | D30: Discountpct | E30: Quantity | F30: ScenarioDiscount | G30: ScenarioUnitCost | H30: ScenarioQty | I30: ScenarioRevenue | J30: ScenarioProfit | K30: ScenarioCOGS
A31: =Original!A21 -> ORD-2025-745263 | B31: =Original!R21 -> 1015.16 | C31: =Original!S21 -> 2148.14 | D31: =Original!T21 -> 0.038 | E31: =Original!V21 -> 19 | F31: =MIN(D31,$B$2) -> 0.038 | G31: =B31*(1+$B$3) -> 1116.676 | H31: =E31*(1+$B$4) -> 19 | I31: =C31*H31*(1-F31) -> 39263.703 | J31: =I31-K31 -> 18046.859 | K31: =G31*H31 -> 21216.844
A32: =Original!A22 -> ORD-2024-798002 | B32: =Original!R22 -> 1494.4 | C32: =Original!S22 -> 3661.07 | D32: =Original!T22 -> 0.072 | E32: =Original!V22 -> 7 | F32: =MIN(D32,$B$2) -> 0.05 | G32: =B32*(1+$B$3) -> 1643.84 | H32: =E32*(1+$B$4) -> 7 | I32: =C32*H32*(1-F32) -> 24346.115 | J32: =I32-K32 -> 12839.235 | K32: =G32*H32 -> 11506.88
A33: =Original!A23 -> ORD-2023-867836 | B33: =Original!R23 -> 1331.19 | C33: =Original!S23 -> 2903.09 | D33: =Original!T23 -> 0.143 | E33: =Original!V23 -> 8 | F33: =MIN(D33,$B$2) -> 0.05 | G33: =B33*(1+$B$3) -> 1464.309 | H33: =E33*(1+$B$4) -> 8 | I33: =C33*H33*(1-F33) -> 22063.484 | J33: =I33-K33 -> 10349.012 | K33: =G33*H33 -> 11714.472
A34: =Original!A24 -> ORD-2025-580047 | B34: =Original!R24 -> 730.99 | C34: =Original!S24 -> 1242.84 | D34: =Original!T24 -> 0.12 | E34: =Original!V24 -> 10 | F34: =MIN(D34,$B$2) -> 0.05 | G34: =B34*(1+$B$3) -> 804.089 | H34: =E34*(1+$B$4) -> 10 | I34: =C34*H34*(1-F34) -> 11806.98 | J34: =I34-K34 -> 3766.09 | K34: =G34*H34 -> 8040.89
A35: =Original!A25 -> ORD-2024-500109 | B35: =Original!R25 -> 1274.59 | C35: =Original!S25 -> 2553.69 | D35: =Original!T25 -> 0.01 | E35: =Original!V25 -> 8 | F35: =MIN(D35,$B$2) -> 0.01 | G35: =B35*(1+$B$3) -> 1402.049 | H35: =E35*(1+$B$4) -> 8 | I35: =C35*H35*(1-F35) -> 20225.225 | J35: =I35-K35 -> 9008.8328 | K35: =G35*H35 -> 11216.392
A36: =Original!A26 -> ORD-2023-271836 | B36: =Original!R26 -> 948.55 | C36: =Original!S26 -> 2089.16 | D36: =Original!T26 -> 0.007 | E36: =Original!V26 -> 12 | F36: =MIN(D36,$B$2) -> 0.007 | G36: =B36*(1+$B$3) -> 1043.405 | H36: =E36*(1+$B$4) -> 12 | I36: =C36*H36*(1-F36) -> 24894.431 | J36: =I36-K36 -> 12373.571 | K36: =G36*H36 -> 12520.86
A37: =Original!A27 -> ORD-2024-215294 | B37: =Original!R27 -> 1491.85 | C37: =Original!S27 -> 2583.02 | D37: =Original!T27 -> 0.168 | E37: =Original!V27 -> 4 | F37: =MIN(D37,$B$2) -> 0.05 | G37: =B37*(1+$B$3) -> 1641.035 | H37: =E37*(1+$B$4) -> 4 | I37: =C37*H37*(1-F37) -> 9815.476 | J37: =I37-K37 -> 3251.336 | K37: =G37*H37 -> 6564.14
A38: =Original!A28 -> ORD-2024-788105 | B38: =Original!R28 -> 117.64 | C38: =Original!S28 -> 175.67 | D38: =Original!T28 -> 0 | E38: =Original!V28 -> 10 | F38: =MIN(D38,$B$2) -> 0 | G38: =B38*(1+$B$3) -> 129.404 | H38: =E38*(1+$B$4) -> 10 | I38: =C38*H38*(1-F38) -> 1756.7 | J38: =I38-K38 -> 462.66 | K38: =G38*H38 -> 1294.04
A39: =Original!A29 -> ORD-2024-855073 | B39: =Original!R29 -> 857.24 | C39: =Original!S29 -> 758.23 | D39: =Original!T29 -> 0.125 | E39: =Original!V29 -> 6 | F39: =MIN(D39,$B$2) -> 0.05 | G39: =B39*(1+$B$3) -> 942.964 | H39: =E39*(1+$B$4) -> 6 | I39: =C39*H39*(1-F39) -> 4321.911 | J39: =I39-K39 -> -1335.873 | K39: =G39*H39 -> 5657.784
A40: =Original!A30 -> ORD-2023-897079 | B40: =Original!R30 -> 209.25 | C40: =Original!S30 -> 434.8 | D40: =Original!T30 -> 0 | E40: =Original!V30 -> 9 | F40: =MIN(D40,$B$2) -> 0 | G40: =B40*(1+$B$3) -> 230.175 | H40: =E40*(1+$B$4) -> 9 | I40: =C40*H40*(1-F40) -> 3913.2 | J40: =I40-K40 -> 1841.625 | K40: =G40*H40 -> 2071.575
A41: =Original!A31 -> ORD-2025-548982 | B41: =Original!R31 -> 754.77 | C41: =Original!S31 -> 1666.18 | D41: =Original!T31 -> 0.139 | E41: =Original!V31 -> 14 | F41: =MIN(D41,$B$2) -> 0.05 | G41: =B41*(1+$B$3) -> 830.247 | H41: =E41*(1+$B$4) -> 14 | I41: =C41*H41*(1-F41) -> 22160.194 | J41: =I41-K41 -> 10536.736 | K41: =G41*H41 -> 11623.458
A42: =Original!A32 -> ORD-2024-170313 | B42: =Original!R32 -> 495.59 | C42: =Original!S32 -> 631.78 | D42: =Original!T32 -> 0.087 | E42: =Original!V32 -> 17 | F42: =MIN(D42,$B$2) -> 0.05 | G42: =B42*(1+$B$3) -> 545.149 | H42: =E42*(1+$B$4) -> 17 | I42: =C42*H42*(1-F42) -> 10203.247 | J42: =I42-K42 -> 935.714 | K42: =G42*H42 -> 9267.533
... A662: =Original!A652 -> 0 | B662: =Original!R652 -> 0 | C662: =Original!S652 -> 0 | D662: =Original!T652 -> 0 | E662: =Original!V652 -> 0 | F662: =MIN(D662,$B$2) -> 0 | G662: =B662*(1+$B$3) -> 0 | H662: =E662*(1+$B$4) -> 0 | I662: =C662*H662*(1-F662) -> 0 | J662: =I662-K662 -> 0 | K662: =G662*H662 -> 0

Sheet service_level_proxy
A3: Average of 7Target | B3: Column Labels
A4: Row Labels | B4: Accessories | C4: Components | D4: Laptops | E4: Monitors | F4: Networking | G4: Phones | H4: Printers | I4: Grand Total
A5: Brazil | B5: 0.3 | C5: 0.14285714 | D5: 0.2 | E5: 0.083333333 | F5: 0.16666667 | G5: 0.44444444 | H5: 0.14285714 | I5: 0.20967742
A6: Canada | B6: 0.16666667 | C6: 0.33333333 | D6: 0.33333333 | E6: 0 | F6: 0 | G6: 0 | H6: 0.076923077 | I6: 0.13636364
A7: China | B7: 0.75 | C7: 0 | D7: 0.2 | E7: 0.16666667 | F7: 0.375 | G7: 0.14285714 | H7: 0 | I7: 0.17647059
A8: France | B8: 0.14285714 | C8: 0.3 | D8: 0.33333333 | E8: 0.3 | F8: 0.16666667 | G8: 0 | H8: 0.16666667 | I8: 0.22222222
A9: Germany | B9: 0.44444444 | C9: 0.33333333 | D9: 0.28571429 | E9: 0 | F9: 0.25 | G9: 0.14285714 | H9: 0.125 | I9: 0.21568627
A10: India | B10: 0.25 | C10: 0.2 | D10: 0.11111111 | E10: 0.16666667 | F10: 0.14285714 | G10: 0.22222222 | H10: 0.16666667 | I10: 0.18032787
A11: Japan | B11: 0.2 | C11: 0.25 | D11: 0.28571429 | E11: 0.28571429 | F11: 0 | G11: 0.090909091 | H11: 0.22222222 | I11: 0.16949153
A12: Kenya | B12: 0.4 | C12: 0.2 | D12: 0.5 | E12: 0 | F12: 0.33333333 | G12: 0.13333333 | H12: 0.125 | I12: 0.26785714
A13: Nigeria | B13: 0.30769231 | C13: 0.16666667 | D13: 0.5 | E13: 0.6 | F13: 0.5 | G13: 0.16666667 | H13: 0.16666667 | I13: 0.31818182
A14: South Africa | B14: 0.5 | C14: 0.18181818 | D14: 0 | E14: 0.14285714 | F14: 0.28571429 | G14: 0.5 | H14: 0.2 | I14: 0.22222222
A15: United Kingdom | B15: 0.125 | C15: 0.28571429 | D15: 0.33333333 | E15: 0.28571429 | F15: 0.22222222 | G15: 0 | H15: 0.3 | I15: 0.24074074
A16: USA | B16: 0.5 | C16: 0.4 | D16: 0.2 | E16: 0 | F16: 0.2 | G16: 0.1 | H16: 0.75 | I16: 0.2745098
A17: Grand Total | B17: 0.31818182 | C17: 0.21978022 | D17: 0.2804878 | E17: 0.15957447 | F17: 0.19767442 | G17: 0.17045455 | H17: 0.19417476 | I17: 0.21835443
K22: Region, Country, Channel, ProductCategory, Month, and Salesperson.

Sheet Dashboard
AA34: Discount cap
Z35: =AH64 -> 0 | AA35: 0 | AB35: 0.05 | AC35: 0.1 | AD35: 0.15 | AE35: 0.2
Y36: quantity uplift | Z36: 0 | AA36: 19975.663 | AB36: 19975.663 | AC36: 19975.663 | AD36: 19975.663 | AE36: 19975.663
Z37: 0.05 | AA37: 19011.261 | AB37: 19011.261 | AC37: 19011.261 | AD37: 19011.261 | AE37: 19011.261
Z38: 0.1 | AA38: 18046.859 | AB38: 18046.859 | AC38: 18046.859 | AD38: 18046.859 | AE38: 18046.859
Z39: 0.15 | AA39: 17082.457 | AB39: 17082.457 | AC39: 17082.457 | AD39: 17082.457 | AE39: 17082.457
Z40: 0.2 | AA40: 16118.055 | AB40: 16118.055 | AC40: 16118.055 | AD40: 16118.055 | AE40: 16118.055

Sheet Assignment
A1: Assignment
A2: Excel Mastery Assignment: Sales Operations & Analytics
A4: Overview:
A5: You are an analyst for a multi-regional electronics distributor. The 'Data' sheet contains 632 rows and 15 columns of transactional data with intentional data-quality issues.
A6: Your job is to clean, enrich, analyze, and present insights via a dynamic dashboard.
A8: Part A — Data Cleaning & Preparation:
A9: 1) Create a staging table where you:
A10: • Remove exact duplicate rows (define and document your duplicate criteria).-----there were no duplicates
A11: • Fix data types (dates as Dates, numeric fields as numbers).----done
A12: • Handle missing values for City, Salesperson, and Channel using reasonable business logic (document your approach).-----we filled with unknown because they were mainly text columns with blanks
A13: • Flag and correct suspicious UnitPrice values (e.g., negative prices) and discounts (e.g., > 30%).highlighted the anomaly data in discount column with red ,,,, we decided to leave them
A14: • Ensure RequiredDate is not earlier than OrderDate; where it is, impute a corrected RequiredDate (explain your rule).
... A67: 15) Ensure your dashboard responds to slicers without broken references.

Sheet revenue by month
A3: Row Labels | B3: Sum of GrossRevenue
A4: Apr-2023 | B4: 371604.58
A5: Apr-2024 | B5: 239506.83
A6: Apr-2025 | B6: 336135.17
A7: Aug-2023 | B7: 339044.67
A8: Aug-2024 | B8: 383755.42
A9: Aug-2025 | B9: 366808.72
A10: Dec-2023 | B10: 382101.37
A11: Dec-2024 | B11: 354378.94
A12: Feb-2023 | B12: 433788.64
A13: Feb-2024 | B13: 307793.71
A14: Feb-2025 | B14: 221608.5
A15: Jan-2023 | B15: 178642.74
... A37: Grand Total | B37: 10928846

Sheet profit by region and channel
A3: Sum of GrossProfit | B3: Column Labels
A4: Row Labels | B4: Africa | C4: Americas | D4: Asia | E4: Europe | F4: Grand Total
A5: Direct | B5: 177919.82 | C5: 258674.93 | D5: 229217.48 | E5: 292716.95 | F5: 958529.18
A6: Distributor | B6: 192042.35 | C6: 175298.68 | D6: 151146.75 | E6: 105550.85 | F6: 624038.63
A7: Marketplace | B7: 164839.3 | C7: 96609.648 | D7: 128045.01 | E7: 111692.81 | F7: 501186.77
A8: Online | B8: 145453.95 | C8: 261943.84 | D8: 149042.39 | E8: 200067.16 | F8: 756507.34
A9: Retail | B9: 141171.08 | C9: 69035.709 | D9: 153258.56 | E9: 151779.17 | F9: 515244.53
A10: unknown | B10: 16237.344 | C10: 777.96 | D10: 20547.545 | E10: 8028.7065 | F10: 45591.556
A11: Grand Total | B11: 837663.85 | C11: 862340.77 | D11: 831257.73 | E11: 869835.66 | F11: 3401098

Sheet Top 10 SKUs by Revenue (bar)
A3: Row Labels | B3: Sum of GrossRevenue
A4: CMP-8851 | B4: 139277.83
A5: NET-2365 | B5: 109244
A6: LAP-8910 | B6: 102122.94
A7: MON-6962 | B7: 92715.25
A8: MON-2266 | B8: 87404.93
A9: MON-6699 | B9: 85637.74
A10: CMP-3938 | B10: 84136.12
A11: LAP-3904 | B11: 82514.712
A12: NET-5987 | B12: 82141.34
A13: NET-5523 | B13: 79548.756
A14: Grand Total | B14: 944743.62

Sheet Original
A1: OrderID | B1: OrderDate | C1: Quarter | D1: Standardized-o-date | E1: RequiredDate | F1: LeadTimeDays | G1: 7Target | H1: updated_reqdate | I1: Region | J1: Country | K1: City | L1: CustomerSegment | M1: Channel | N1: Salesperson | O1: ProductCategory | P1: PriceBand | Q1: SKU | R1: UnitCost | S1: UnitPrice | T1: DiscountPct | U1: DiscountFlag | V1: Quantity | W1: date_status | X1: diff(date) | Y1: Absolute_days_diff | Z1: GrossRevenue | AA1: CostOfGoods | AB1: GrossProfit | AC1: Q1 | AD1: Q2 | AE1: Q3 | AF1: PriceBand2 | AG1: MarginPct | AH1: FirstCoutryOrderDate | AI1: CohortMonth
A2: ORD-2024-275203 | B2: 45362 | C2: ="Q" & ROUNDUP(MONTH(B2)/3,0) & "-" & YEAR(B2) -> Q1-2024 | D2: =TEXT(B2,"MMM-YYYY") -> Mar-2024 | E2: 45388 | F2: =H2-B2 -> 26 | G2: =IF(F2<=7, 1, 0) -> 0 | H2: =IF(E2<B2,B2+14,E2) -> 45388 | I2: Africa | J2: Kenya | K2: Kisumu | L2: Corporate | M2: Retail | N2: C. Otieno | O2: Components | P2: {=_xlfn.IFS(S2<=PERCENTILE($S$2:$S$1000, 0.33), "Low", S2<=PERCENTILE($S$2:$S$1000, 0.66), "Medium", TRUE, "High")} -> Low | Q2: CMP-8270 | R2: 279.24 | S2: 608.9 | T2: 0.112 | U2: =IF(T2>0.2,1,0) -> 0 | V2: 9 | W2: =IF(E2>B2, "ok", "sus") -> ok | X2: =E2-B2 -> 26 | Y2: =ABS(X2) -> 26 | Z2: =S2*V2*(1-T2) -> 4866.3288 | AA2: =R2*V2 -> 2513.16 | AB2: =Z2-AA2 -> 2353.1688 | AC2: =_xlfn.QUARTILE.INC(S:S,1) -> 606.3775 | AD2: =_xlfn.QUARTILE.INC(S:S,2) -> 1193.865 | AE2: =_xlfn.QUARTILE.INC(S:S,3) -> 1912.045 | AF2: =IF(S1<=$AC$2,"Low", IF(S1<=$AE$3,"Medium", "High")) -> High | AG2: =IF(Z2=0,0,AB2/Z2) -> 0.48356141 | AH2: =_xlfn.MINIFS($B:$B,$J:$J,J2) -> 44946 | AI2: =TEXT(AH2,"MMM-YYYY") -> Jan-2023
A3: ORD-2024-358795 | B3: 45588 | C3: ="Q" & ROUNDUP(MONTH(B3)/3,0) & "-" & YEAR(B3) -> Q4-2024 | D3: =TEXT(B3,"MMM-YYYY") -> Oct-2024 | E3: 45587 | F3: =H3-B3 -> 14 | G3: =IF(F3<=7, 1, 0) -> 0 | H3: =IF(E3<B3,B3+14,E3) -> 45602 | I3: Africa | J3: Nigeria | K3: Port Harcourt | L3: Education | M3: Online | N3: J. Njeri | O3: Printers | P3: {=_xlfn.IFS(S3<=PERCENTILE($S$2:$S$1000, 0.33), "Low", S3<=PERCENTILE($S$2:$S$1000, 0.66), "Medium", TRUE, "High")} -> Low | Q3: PRN-9322 | R3: 1084.39 | S3: 759.33 | T3: 0.237 | U3: =IF(T3>0.2,1,0) -> 1 | V3: 31 | W3: =IF(E3>B3, "ok", "sus") -> sus | X3: =E3-B3 -> -1 | Y3: =ABS(X3) -> 1 | Z3: =S3*V3*(1-T3) -> 17960.432 | AA3: =R3*V3 -> 33616.09 | AB3: =Z3-AA3 -> -15655.658 | AC3: =_xlfn.QUARTILE.INC(S:S,1) -> 606.3775 | AD3: =_xlfn.QUARTILE.INC(S:S,2) -> 1193.865 | AE3: =_xlfn.QUARTILE.INC(S:S,3) -> 1912.045 | AF3: =IF(S2<=$AC$2,"Low", IF(S2<=$AE$3,"Medium", "High")) -> Medium | AG3: =IF(Z3=0,0,AB3/Z3) -> -0.87167486 | AH3: =_xlfn.MINIFS($B:$B,$J:$J,J3) -> 44941 | AI3: =TEXT(AH3,"MMM-YYYY") -> Jan-2023
A4: ORD-2023-373538 | B4: 44985 | C4: ="Q" & ROUNDUP(MONTH(B4)/3,0) & "-" & YEAR(B4) -> Q1-2023 | D4: =TEXT(B4,"MMM-YYYY") -> Feb-2023 | E4: 45010 | F4: =H4-B4 -> 25 | G4: =IF(F4<=7, 1, 0) -> 0 | H4: =IF(E4<B4,B4+14,E4) -> 45010 | I4: Africa | J4: Kenya | K4: Nairobi | L4: Corporate | M4: Retail | N4: I. Johnson | O4: Networking | P4: {=_xlfn.IFS(S4<=PERCENTILE($S$2:$S$1000, 0.33), "Low", S4<=PERCENTILE($S$2:$S$1000, 0.66), "Medium", TRUE, "High")} -> Low | Q4: NET-9666 | R4: 1460.76 | S4: 30.66 | T4: 0.131 | U4: =IF(T4>0.2,1,0) -> 0 | V4: 12 | W4: =IF(E4>B4, "ok", "sus") -> ok | X4: =E4-B4 -> 25 | Y4: =ABS(X4) -> 25 | Z4: =S4*V4*(1-T4) -> 319.72248 | AA4: =R4*V4 -> 17529.12 | AB4: =Z4-AA4 -> -17209.398 | AC4: =_xlfn.QUARTILE.INC(S:S,1) -> 606.3775 | AD4: =_xlfn.QUARTILE.INC(S:S,2) -> 1193.865 | AE4: =_xlfn.QUARTILE.INC(S:S,3) -> 1912.045 | AF4: =IF(S3<=$AC$2,"Low", IF(S3<=$AE$3,"Medium", "High")) -> Medium | AG4: =IF(Z4=0,0,AB4/Z4) -> -53.826048 | AH4: =_xlfn.MINIFS($B:$B,$J:$J,J4) -> 44946 | AI4: =TEXT(AH4,"MMM-YYYY") -> Jan-2023
A5: ORD-2025-168148 | B5: 45745 | C5: ="Q" & ROUNDUP(MONTH(B5)/3,0) & "-" & YEAR(B5) -> Q1-2025 | D5: =TEXT(B5,"MMM-YYYY") -> Mar-2025 | E5: 45749 | F5: =H5-B5 -> 4 | G5: =IF(F5<=7, 1, 0) -> 1 | H5: =IF(E5<B5,B5+14,E5) -> 45749 | I5: Africa | J5: Nigeria | K5: Lagos | L5: Non-Profit | M5: Marketplace | N5: G. Dubois | O5: Phones | P5: {=_xlfn.IFS(S5<=PERCENTILE($S$2:$S$1000, 0.33), "Low", S5<=PERCENTILE($S$2:$S$1000, 0.66), "Medium", TRUE, "High")} -> Low | Q5: PHN-4556 | R5: 259.93 | S5: 255.94 | T5: 0.072 | U5: =IF(T5>0.2,1,0) -> 0 | V5: 22 | W5: =IF(E5>B5, "ok", "sus") -> ok | X5: =E5-B5 -> 4 | Y5: =ABS(X5) -> 4 | Z5: =S5*V5*(1-T5) -> 5225.271 | AA5: =R5*V5 -> 5718.46 | AB5: =Z5-AA5 -> -493.18896 | AC5: =_xlfn.QUARTILE.INC(S:S,1) -> 606.3775 | AD5: =_xlfn.QUARTILE.INC(S:S,2) -> 1193.865 | AE5: =_xlfn.QUARTILE.INC(S:S,3) -> 1912.045 | AF5: =IF(S4<=$AC$2,"Low", IF(S4<=$AE$3,"Medium", "High")) -> Low | AG5: =IF(Z5=0,0,AB5/Z5) -> -0.094385335 | AH5: =_xlfn.MINIFS($B:$B,$J:$J,J5) -> 44941 | AI5: =TEXT(AH5,"MMM-YYYY") -> Jan-2023
A6: ORD-2023-824839 | B6: 45266 | C6: ="Q" & ROUNDUP(MONTH(B6)/3,0) & "-" & YEAR(B6) -> Q4-2023 | D6: =TEXT(B6,"MMM-YYYY") -> Dec-2023 | E6: 45291 | F6: =H6-B6 -> 25 | G6: =IF(F6<=7, 1, 0) -> 0 | H6: =IF(E6<B6,B6+14,E6) -> 45291 | I6: Asia | J6: Japan | K6: Osaka | L6: Consumer | M6: Retail | N6: L. Okafor | O6: Printers | P6: {=_xlfn.IFS(S6<=PERCENTILE($S$2:$S$1000, 0.33), "Low", S6<=PERCENTILE($S$2:$S$1000, 0.66), "Medium", TRUE, "High")} -> Low | Q6: PRN-8041 | R6: 663.03 | S6: 813.51 | T6: 0.102 | U6: =IF(T6>0.2,1,0) -> 0 | V6: 15 | W6: =IF(E6>B6, "ok", "sus") -> ok | X6: =E6-B6 -> 25 | Y6: =ABS(X6) -> 25 | Z6: =S6*V6*(1-T6) -> 10957.98 | AA6: =R6*V6 -> 9945.45 | AB6: =Z6-AA6 -> 1012.5297 | AC6: =_xlfn.QUARTILE.INC(S:S,1) -> 606.3775 | AD6: =_xlfn.QUARTILE.INC(S:S,2) -> 1193.865 | AE6: =_xlfn.QUARTILE.INC(S:S,3) -> 1912.045 | AF6: =IF(S5<=$AC$2,"Low", IF(S5<=$AE$3,"Medium", "High")) -> Low | AG6: =IF(Z6=0,0,AB6/Z6) -> 0.092401129 | AH6: =_xlfn.MINIFS($B:$B,$J:$J,J6) -> 44988 | AI6: =TEXT(AH6,"MMM-YYYY") -> Mar-2023
A7: ORD-2023-723587 | B7: 44928 | C7: ="Q" & ROUNDUP(MONTH(B7)/3,0) & "-" & YEAR(B7) -> Q1-2023 | D7: =TEXT(B7,"MMM-YYYY") -> Jan-2023 | E7: 44931 | F7: =H7-B7 -> 3 | G7: =IF(F7<=7, 1, 0) -> 1 | H7: =IF(E7<B7,B7+14,E7) -> 44931 | I7: Americas | J7: Canada | K7: Toronto | L7: Corporate | M7: Distributor | N7: B. Chen | O7: Laptops | P7: {=_xlfn.IFS(S7<=PERCENTILE($S$2:$S$1000, 0.33), "Low", S7<=PERCENTILE($S$2:$S$1000, 0.66), "Medium", TRUE, "High")} -> Low | Q7: LAP-8555 | R7: 315.87 | S7: 591.68 | T7: 0 | U7: =IF(T7>0.2,1,0) -> 0 | V7: 7 | W7: =IF(E7>B7, "ok", "sus") -> ok | X7: =E7-B7 -> 3 | Y7: =ABS(X7) -> 3 | Z7: =S7*V7*(1-T7) -> 4141.76 | AA7: =R7*V7 -> 2211.09 | AB7: =Z7-AA7 -> 1930.67 | AC7: =_xlfn.QUARTILE.INC(S:S,1) -> 606.3775 | AD7: =_xlfn.QUARTILE.INC(S:S,2) -> 1193.865 | AE7: =_xlfn.QUARTILE.INC(S:S,3) -> 1912.045 | AF7: =IF(S6<=$AC$2,"Low", IF(S6<=$AE$3,"Medium", "High")) -> Medium | AG7: =IF(Z7=0,0,AB7/Z7) -> 0.46614724 | AH7: =_xlfn.MINIFS($B:$B,$J:$J,J7) -> 44928 | AI7: =TEXT(AH7,"MMM-YYYY") -> Jan-2023
A8: ORD-2024-336584 | B8: 45653 | C8: ="Q" & ROUNDUP(MONTH(B8)/3,0) & "-" & YEAR(B8) -> Q4-2024 | D8: =TEXT(B8,"MMM-YYYY") -> Dec-2024 | E8: 45671 | F8: =H8-B8 -> 18 | G8: =IF(F8<=7, 1, 0) -> 0 | H8: =IF(E8<B8,B8+14,E8) -> 45671 | I8: Asia | J8: India | K8: Bengaluru | L8: Small Business | M8: Marketplace | N8: E. Garcia | O8: Monitors | P8: {=_xlfn.IFS(S8<=PERCENTILE($S$2:$S$1000, 0.33), "Low", S8<=PERCENTILE($S$2:$S$1000, 0.66), "Medium", TRUE, "High")} -> Medium | Q8: MON-8629 | R8: 586.07 | S8: 845.97 | T8: 0.147 | U8: =IF(T8>0.2,1,0) -> 0 | V8: 4 | W8: =IF(E8>B8, "ok", "sus") -> ok | X8: =E8-B8 -> 18 | Y8: =ABS(X8) -> 18 | Z8: =S8*V8*(1-T8) -> 2886.4496 | AA8: =R8*V8 -> 2344.28 | AB8: =Z8-AA8 -> 542.16964 | AC8: =_xlfn.QUARTILE.INC(S:S,1) -> 606.3775 | AD8: =_xlfn.QUARTILE.INC(S:S,2) -> 1193.865 | AE8: =_xlfn.QUARTILE.INC(S:S,3) -> 1912.045 | AF8: =IF(S7<=$AC$2,"Low", IF(S7<=$AE$3,"Medium", "High")) -> Low | AG8: =IF(Z8=0,0,AB8/Z8) -> 0.1878327 | AH8: =_xlfn.MINIFS($B:$B,$J:$J,J8) -> 44955 | AI8: =TEXT(AH8,"MMM-YYYY") -> Jan-2023
A9: ORD-2023-112666 | B9: 44941 | C9: ="Q" & ROUNDUP(MONTH(B9)/3,0) & "-" & YEAR(B9) -> Q1-2023 | D9: =TEXT(B9,"MMM-YYYY") -> Jan-2023 | E9: 44939 | F9: =H9-B9 -> 14 | G9: =IF(F9<=7, 1, 0) -> 0 | H9: =IF(E9<B9,B9+14,E9) -> 44955 | I9: Africa | J9: Nigeria | K9: Abuja | L9: Education | M9: Online | N9: O. Wang | O9: Printers | P9: {=_xlfn.IFS(S9<=PERCENTILE($S$2:$S$1000, 0.33), "Low", S9<=PERCENTILE($S$2:$S$1000, 0.66), "Medium", TRUE, "High")} -> Low | Q9: PRN-6276 | R9: 28.38 | S9: 47.22 | T9: 0.194 | U9: =IF(T9>0.2,1,0) -> 0 | V9: 18 | W9: =IF(E9>B9, "ok", "sus") -> sus | X9: =E9-B9 -> -2 | Y9: =ABS(X9) -> 2 | Z9: =S9*V9*(1-T9) -> 685.06776 | AA9: =R9*V9 -> 510.84 | AB9: =Z9-AA9 -> 174.22776 | AC9: =_xlfn.QUARTILE.INC(S:S,1) -> 606.3775 | AD9: =_xlfn.QUARTILE.INC(S:S,2) -> 1193.865 | AE9: =_xlfn.QUARTILE.INC(S:S,3) -> 1912.045 | AF9: =IF(S8<=$AC$2,"Low", IF(S8<=$AE$3,"Medium", "High")) -> Medium | AG9: =IF(Z9=0,0,AB9/Z9) -> 0.25432194 | AH9: =_xlfn.MINIFS($B:$B,$J:$J,J9) -> 44941 | AI9: =TEXT(AH9,"MMM-YYYY") -> Jan-2023
A10: ORD-2024-589570 | B10: 45416 | C10: ="Q" & ROUNDUP(MONTH(B10)/3,0) & "-" & YEAR(B10) -> Q2-2024 | D10: =TEXT(B10,"MMM-YYYY") -> May-2024 | E10: 45441 | F10: =H10-B10 -> 25 | G10: =IF(F10<=7, 1, 0) -> 0 | H10: =IF(E10<B10,B10+14,E10) -> 45441 | I10: Africa | J10: Nigeria | K10: Abuja | L10: Non-Profit | M10: Marketplace | N10: O. Wang | O10: Monitors | P10: {=_xlfn.IFS(S10<=PERCENTILE($S$2:$S$1000, 0.33), "Low", S10<=PERCENTILE($S$2:$S$1000, 0.66), "Medium", TRUE, "High")} -> High | Q10: MON-6892 | R10: 1295.34 | S10: 2530.81 | T10: 0.031 | U10: =IF(T10>0.2,1,0) -> 0 | V10: 6 | W10: =IF(E10>B10, "ok", "sus") -> ok | X10: =E10-B10 -> 25 | Y10: =ABS(X10) -> 25 | Z10: =S10*V10*(1-T10) -> 14714.129 | AA10: =R10*V10 -> 7772.04 | AB10: =Z10-AA10 -> 6942.0893 | AC10: =_xlfn.QUARTILE.INC(S:S,1) -> 606.3775 | AD10: =_xlfn.QUARTILE.INC(S:S,2) -> 1193.865 | AE10: =_xlfn.QUARTILE.INC(S:S,3) -> 1912.045 | AF10: =IF(S9<=$AC$2,"Low", IF(S9<=$AE$3,"Medium", "High")) -> Low | AG10: =IF(Z10=0,0,AB10/Z10) -> 0.47179749 | AH10: =_xlfn.MINIFS($B:$B,$J:$J,J10) -> 44941 | AI10: =TEXT(AH10,"MMM-YYYY") -> Jan-2023
A11: ORD-2025-997421 | B11: 45798 | C11: ="Q" & ROUNDUP(MONTH(B11)/3,0) & "-" & YEAR(B11) -> Q2-2025 | D11: =TEXT(B11,"MMM-YYYY") -> May-2025 | E11: 45817 | F11: =H11-B11 -> 19 | G11: =IF(F11<=7, 1, 0) -> 0 | H11: =IF(E11<B11,B11+14,E11) -> 45817 | I11: Americas | J11: Brazil | K11: São Paulo | L11: Non-Profit | M11: Online | N11: A. Patel | O11: Components | P11: {=_xlfn.IFS(S11<=PERCENTILE($S$2:$S$1000, 0.33), "Low", S11<=PERCENTILE($S$2:$S$1000, 0.66), "Medium", TRUE, "High")} -> High | Q11: CMP-3731 | R11: 1331.38 | S11: 2309.56 | T11: 0.149 | U11: =IF(T11>0.2,1,0) -> 0 | V11: 31 | W11: =IF(E11>B11, "ok", "sus") -> ok | X11: =E11-B11 -> 19 | Y11: =ABS(X11) -> 19 | Z11: =S11*V11*(1-T11) -> 60928.502 | AA11: =R11*V11 -> 41272.78 | AB11: =Z11-AA11 -> 19655.722 | AC11: =_xlfn.QUARTILE.INC(S:S,1) -> 606.3775 | AD11: =_xlfn.QUARTILE.INC(S:S,2) -> 1193.865 | AE11: =_xlfn.QUARTILE.INC(S:S,3) -> 1912.045 | AF11: =IF(S10<=$AC$2,"Low", IF(S10<=$AE$3,"Medium", "High")) -> High | AG11: =IF(Z11=0,0,AB11/Z11) -> 0.32260308 | AH11: =_xlfn.MINIFS($B:$B,$J:$J,J11) -> 44955 | AI11: =TEXT(AH11,"MMM-YYYY") -> Jan-2023
A12: ORD-2024-210687 | B12: 45319 | C12: ="Q" & ROUNDUP(MONTH(B12)/3,0) & "-" & YEAR(B12) -> Q1-2024 | D12: =TEXT(B12,"MMM-YYYY") -> Jan-2024 | E12: 45331 | F12: =H12-B12 -> 12 | G12: =IF(F12<=7, 1, 0) -> 0 | H12: =IF(E12<B12,B12+14,E12) -> 45331 | I12: Europe | J12: Germany | K12: Berlin | L12: Corporate | M12: Online | N12: G. Dubois | O12: Accessories | P12: {=_xlfn.IFS(S12<=PERCENTILE($S$2:$S$1000, 0.33), "Low", S12<=PERCENTILE($S$2:$S$1000, 0.66), "Medium", TRUE, "High")} -> Low | Q12: ACC-7938 | R12: 644.17 | S12: 700.12 | T12: 0.006 | U12: =IF(T12>0.2,1,0) -> 0 | V12: 23 | W12: =IF(E12>B12, "ok", "sus") -> ok | X12: =E12-B12 -> 12 | Y12: =ABS(X12) -> 12 | Z12: =S12*V12*(1-T12) -> 16006.143 | AA12: =R12*V12 -> 14815.91 | AB12: =Z12-AA12 -> 1190.2334 | AC12: =_xlfn.QUARTILE.INC(S:S,1) -> 606.3775 | AD12: =_xlfn.QUARTILE.INC(S:S,2) -> 1193.865 | AE12: =_xlfn.QUARTILE.INC(S:S,3) -> 1912.045 | AF12: =IF(S11<=$AC$2,"Low", IF(S11<=$AE$3,"Medium", "High")) -> High | AG12: =IF(Z12=0,0,AB12/Z12) -> 0.074361038 | AH12: =_xlfn.MINIFS($B:$B,$J:$J,J12) -> 44948 | AI12: =TEXT(AH12,"MMM-YYYY") -> Jan-2023
A13: ORD-2025-515515 | B13: 45660 | C13: ="Q" & ROUNDUP(MONTH(B13)/3,0) & "-" & YEAR(B13) -> Q1-2025 | D13: =TEXT(B13,"MMM-YYYY") -> Jan-2025 | E13: 45680 | F13: =H13-B13 -> 20 | G13: =IF(F13<=7, 1, 0) -> 0 | H13: =IF(E13<B13,B13+14,E13) -> 45680 | I13: Asia | J13: Japan | K13: Osaka | L13: Corporate | M13: Distributor | N13: F. Müller | O13: Phones | P13: {=_xlfn.IFS(S13<=PERCENTILE($S$2:$S$1000, 0.33), "Low", S13<=PERCENTILE($S$2:$S$1000, 0.66), "Medium", TRUE, "High")} -> Low | Q13: PHN-7019 | R13: 908.6 | S13: 691.37 | T13: 0.25 | U13: =IF(T13>0.2,1,0) -> 1 | V13: 20 | W13: =IF(E13>B13, "ok", "sus") -> ok | X13: =E13-B13 -> 20 | Y13: =ABS(X13) -> 20 | Z13: =S13*V13*(1-T13) -> 10370.55 | AA13: =R13*V13 -> 18172 | AB13: =Z13-AA13 -> -7801.45 | AC13: =_xlfn.QUARTILE.INC(S:S,1) -> 606.3775 | AD13: =_xlfn.QUARTILE.INC(S:S,2) -> 1193.865 | AE13: =_xlfn.QUARTILE.INC(S:S,3) -> 1912.045 | AF13: =IF(S12<=$AC$2,"Low", IF(S12<=$AE$3,"Medium", "High")) -> Medium | AG13: =IF(Z13=0,0,AB13/Z13) -> -0.75226965 | AH13: =_xlfn.MINIFS($B:$B,$J:$J,J13) -> 44988 | AI13: =TEXT(AH13,"MMM-YYYY") -> Mar-2023
... A130: ORD-2024-605518 | B130: 45442 | C130: ="Q" & ROUNDUP(MONTH(B130)/3,0) & "-" & YEAR(B130) -> Q2-2024 | D130: =TEXT(B130,"MMM-YYYY") -> May-2024 | E130: 45456 | F130: =H130-B130 -> 14 | G130: =IF(F130<=7, 1, 0) -> 0 | H130: =IF(E130<B130,B130+14,E130) -> 45456 | I130: Americas | J130: USA | K130: San Francisco | L130: Small Business | M130: Retail | N130: F. Müller | O130: Phones | P130: {=_xlfn.IFS(S130<=PERCENTILE($S$2:$S$1000, 0.33), "Low", S130<=PERCENTILE($S$2:$S$1000, 0.66), "Medium", TRUE, "High")} -> Low | Q130: PHN-4356 | R130: 157.78 | S130: 361.1 | T130: 0.187 | U130: =IF(T130>0.2,1,0) -> 0 | V130: 9 | W130: =IF(E130>B130, "ok", "sus") -> ok | X130: =E130-B130 -> 14 | Y130: =ABS(X130) -> 14 | Z130: =S130*V130*(1-T130) -> 2642.1687 | AA130: =R130*V130 -> 1420.02 | AB130: =Z130-AA130 -> 1222.1487 | AC130: =_xlfn.QUARTILE.INC(S:S,1) -> 606.3775 | AD130: =_xlfn.QUARTILE.INC(S:S,2) -> 1193.865 | AE130: =_xlfn.QUARTILE.INC(S:S,3) -> 1912.045 | AF130: =IF(S129<=$AC$2,"Low", IF(S129<=$AE$3,"Medium", "High")) -> Low | AG130: =IF(Z130=0,0,AB130/Z130) -> 0.46255514 | AH130: =_xlfn.MINIFS($B:$B,$J:$J,J130) -> 44939 | AI130: =TEXT(AH130,"MMM-YYYY") -> Jan-2023
A131: ORD-2023-521818 | B131: 44948 | C131: ="Q" & ROUNDUP(MONTH(B131)/3,0) & "-" & YEAR(B131) -> Q1-2023 | D131: =TEXT(B131,"MMM-YYYY") -> Jan-2023 | E131: 44956 | F131: =H131-B131 -> 8 | G131: =IF(F131<=7, 1, 0) -> 0 | H131: =IF(E131<B131,B131+14,E131) -> 44956 | I131: Americas | J131: USA | K131: San Francisco | L131: Small Business | M131: Online | N131: A. Patel | O131: Networking | P131: {=_xlfn.IFS(S131<=PERCENTILE($S$2:$S$1000, 0.33), "Low", S131<=PERCENTILE($S$2:$S$1000, 0.66), "Medium", TRUE, "High")} -> Medium | Q131: NET-4155 | R131: 413.52 | S131: 1004.34 | T131: 0.111 | U131: =IF(T131>0.2,1,0) -> 0 | V131: 18 | W131: =IF(E131>B131, "ok", "sus") -> ok | X131: =E131-B131 -> 8 | Y131: =ABS(X131) -> 8 | Z131: =S131*V131*(1-T131) -> 16071.449 | AA131: =R131*V131 -> 7443.36 | AB131: =Z131-AA131 -> 8628.0887 | AC131: =_xlfn.QUARTILE.INC(S:S,1) -> 606.3775 | AD131: =_xlfn.QUARTILE.INC(S:S,2) -> 1193.865 | AE131: =_xlfn.QUARTILE.INC(S:S,3) -> 1912.045 | AF131: =IF(S130<=$AC$2,"Low", IF(S130<=$AE$3,"Medium", "High")) -> Low | AG131: =IF(Z131=0,0,AB131/Z131) -> 0.53685818 | AH131: =_xlfn.MINIFS($B:$B,$J:$J,J3) -> 44941 | AI131: =TEXT(AH131,"MMM-YYYY") -> Jan-2023
A132: ORD-2025-650719 | B132: 45700 | C132: ="Q" & ROUNDUP(MONTH(B132)/3,0) & "-" & YEAR(B132) -> Q1-2025 | D132: =TEXT(B132,"MMM-YYYY") -> Feb-2025 | E132: 45716 | F132: =H132-B132 -> 16 | G132: =IF(F132<=7, 1, 0) -> 0 | H132: =IF(E132<B132,B132+14,E132) -> 45716 | I132: Americas | J132: Brazil | K132: São Paulo | L132: Non-Profit | M132: Direct | N132: B. Chen | O132: Monitors | P132: {=_xlfn.IFS(S132<=PERCENTILE($S$2:$S$1000, 0.33), "Low", S132<=PERCENTILE($S$2:$S$1000, 0.66), "Medium", TRUE, "High")} -> Medium | Q132: MON-5179 | R132: 414.95 | S132: 1027.73 | T132: 0.063 | U132: =IF(T132>0.2,1,0) -> 0 | V132: 8 | W132: =IF(E132>B132, "ok", "sus") -> ok | X132: =E132-B132 -> 16 | Y132: =ABS(X132) -> 16 | Z132: =S132*V132*(1-T132) -> 7703.8641 | AA132: =R132*V132 -> 3319.6 | AB132: =Z132-AA132 -> 4384.2641 | AC132: =_xlfn.QUARTILE.INC(S:S,1) -> 606.3775 | AD132: =_xlfn.QUARTILE.INC(S:S,2) -> 1193.865 | AE132: =_xlfn.QUARTILE.INC(S:S,3) -> 1912.045 | AF132: =IF(S131<=$AC$2,"Low", IF(S131<=$AE$3,"Medium", "High")) -> Medium | AG132: =IF(Z132=0,0,AB132/Z132) -> 0.56909936 | AH132: =_xlfn.MINIFS($B:$B,$J:$J,J4) -> 44946 | AI132: =TEXT(AH132,"MMM-YYYY") -> Jan-2023
A133: ORD-2025-501927 | B133: 45719 | C133: ="Q" & ROUNDUP(MONTH(B133)/3,0) & "-" & YEAR(B133) -> Q1-2025 | D133: =TEXT(B133,"MMM-YYYY") -> Mar-2025 | E133: 45740 | F133: =H133-B133 -> 21 | G133: =IF(F133<=7, 1, 0) -> 0 | H133: =IF(E133<B133,B133+14,E133) -> 45740 | I133: Africa | J133: Nigeria | K133: Abuja | L133: Enterprise | M133: Direct | N133: H. Kim | O133: Accessories | P133: {=_xlfn.IFS(S133<=PERCENTILE($S$2:$S$1000, 0.33), "Low", S133<=PERCENTILE($S$2:$S$1000, 0.66), "Medium", TRUE, "High")} -> Low | Q133: ACC-4056 | R133: 555.95 | S133: 468.09 | T133: 0.142 | U133: =IF(T133>0.2,1,0) -> 0 | V133: 11 | W133: =IF(E133>B133, "ok", "sus") -> ok | X133: =E133-B133 -> 21 | Y133: =ABS(X133) -> 21 | Z133: =S133*V133*(1-T133) -> 4417.8334 | AA133: =R133*V133 -> 6115.45 | AB133: =Z133-AA133 -> -1697.6166 | AC133: =_xlfn.QUARTILE.INC(S:S,1) -> 606.3775 | AD133: =_xlfn.QUARTILE.INC(S:S,2) -> 1193.865 | AE133: =_xlfn.QUARTILE.INC(S:S,3) -> 1912.045 | AF133: =IF(S132<=$AC$2,"Low", IF(S132<=$AE$3,"Medium", "High")) -> Medium | AG133: =IF(Z133=0,0,AB133/Z133) -> -0.38426451 | AH133: =_xlfn.MINIFS($B:$B,$J:$J,J5) -> 44941 | AI133: =TEXT(AH133,"MMM-YYYY") -> Jan-2023
A134: ORD-2023-430904 | B134: 44953 | C134: ="Q" & ROUNDUP(MONTH(B134)/3,0) & "-" & YEAR(B134) -> Q1-2023 | D134: =TEXT(B134,"MMM-YYYY") -> Jan-2023 | E134: 44957 | F134: =H134-B134 -> 4 | G134: =IF(F134<=7, 1, 0) -> 1 | H134: =IF(E134<B134,B134+14,E134) -> 44957 | I134: Europe | J134: United Kingdom | K134: Manchester | L134: Enterprise | M134: Online | N134: N. Brown | O134: Laptops | P134: {=_xlfn.IFS(S134<=PERCENTILE($S$2:$S$1000, 0.33), "Low", S134<=PERCENTILE($S$2:$S$1000, 0.66), "Medium", TRUE, "High")} -> Low | Q134: LAP-9782 | R134: 941.2 | S134: 668.02 | T134: 0.22 | U134: =IF(T134>0.2,1,0) -> 1 | V134: 16 | W134: =IF(E134>B134, "ok", "sus") -> ok | X134: =E134-B134 -> 4 | Y134: =ABS(X134) -> 4 | Z134: =S134*V134*(1-T134) -> 8336.8896 | AA134: =R134*V134 -> 15059.2 | AB134: =Z134-AA134 -> -6722.3104 | AC134: =_xlfn.QUARTILE.INC(S:S,1) -> 606.3775 | AD134: =_xlfn.QUARTILE.INC(S:S,2) -> 1193.865 | AE134: =_xlfn.QUARTILE.INC(S:S,3) -> 1912.045 | AF134: =IF(S133<=$AC$2,"Low", IF(S133<=$AE$3,"Medium", "High")) -> Low | AG134: =IF(Z134=0,0,AB134/Z134) -> -0.80633314 | AH134: =_xlfn.MINIFS($B:$B,$J:$J,J6) -> 44988 | AI134: =TEXT(AH134,"MMM-YYYY") -> Mar-2023
A135: ORD-2025-354346 | B135: 45666 | C135: ="Q" & ROUNDUP(MONTH(B135)/3,0) & "-" & YEAR(B135) -> Q1-2025 | D135: =TEXT(B135,"MMM-YYYY") -> Jan-2025 | E135: 45672 | F135: =H135-B135 -> 6 | G135: =IF(F135<=7, 1, 0) -> 1 | H135: =IF(E135<B135,B135+14,E135) -> 45672 | I135: Asia | J135: China | K135: Beijing | L135: Education | M135: Online | N135: C. Otieno | O135: Phones | P135: {=_xlfn.IFS(S135<=PERCENTILE($S$2:$S$1000, 0.33), "Low", S135<=PERCENTILE($S$2:$S$1000, 0.66), "Medium", TRUE, "High")} -> Low | Q135: PHN-2875 | R135: 304.78 | S135: 537.27 | T135: 0.187 | U135: =IF(T135>0.2,1,0) -> 0 | V135: 8 | W135: =IF(E135>B135, "ok", "sus") -> ok | X135: =E135-B135 -> 6 | Y135: =ABS(X135) -> 6 | Z135: =S135*V135*(1-T135) -> 3494.4041 | AA135: =R135*V135 -> 2438.24 | AB135: =Z135-AA135 -> 1056.1641 | AC135: =_xlfn.QUARTILE.INC(S:S,1) -> 606.3775 | AD135: =_xlfn.QUARTILE.INC(S:S,2) -> 1193.865 | AE135: =_xlfn.QUARTILE.INC(S:S,3) -> 1912.045 | AF135: =IF(S134<=$AC$2,"Low", IF(S134<=$AE$3,"Medium", "High")) -> Medium | AG135: =IF(Z135=0,0,AB135/Z135) -> 0.3022444 | AH135: =_xlfn.MINIFS($B:$B,$J:$J,J7) -> 44928 | AI135: =TEXT(AH135,"MMM-YYYY") -> Jan-2023
A136: ORD-2024-164288 | B136: 45647 | C136: ="Q" & ROUNDUP(MONTH(B136)/3,0) & "-" & YEAR(B136) -> Q4-2024 | D136: =TEXT(B136,"MMM-YYYY") -> Dec-2024 | E136: 45652 | F136: =H136-B136 -> 5 | G136: =IF(F136<=7, 1, 0) -> 1 | H136: =IF(E136<B136,B136+14,E136) -> 45652 | I136: Americas | J136: USA | K136: San Francisco | L136: Consumer | M136: Marketplace | N136: M. Rossi | O136: Printers | P136: {=_xlfn.IFS(S136<=PERCENTILE($S$2:$S$1000, 0.33), "Low", S136<=PERCENTILE($S$2:$S$1000, 0.66), "Medium", TRUE, "High")} -> Low | Q136: PRN-4788 | R136: 699.57 | S136: 572.71 | T136: 0.192 | U136: =IF(T136>0.2,1,0) -> 0 | V136: 26 | W136: =IF(E136>B136, "ok", "sus") -> ok | X136: =E136-B136 -> 5 | Y136: =ABS(X136) -> 5 | Z136: =S136*V136*(1-T136) -> 12031.492 | AA136: =R136*V136 -> 18188.82 | AB136: =Z136-AA136 -> -6157.3283 | AC136: =_xlfn.QUARTILE.INC(S:S,1) -> 606.3775 | AD136: =_xlfn.QUARTILE.INC(S:S,2) -> 1193.865 | AE136: =_xlfn.QUARTILE.INC(S:S,3) -> 1912.045 | AF136: =IF(S135<=$AC$2,"Low", IF(S135<=$AE$3,"Medium", "High")) -> Low | AG136: =IF(Z136=0,0,AB136/Z136) -> -0.51176766 | AH136: =_xlfn.MINIFS($B:$B,$J:$J,J8) -> 44955 | AI136: =TEXT(AH136,"MMM-YYYY") -> Jan-2023
A137: ORD-2023-867285 | B137: 45028 | C137: ="Q" & ROUNDUP(MONTH(B137)/3,0) & "-" & YEAR(B137) -> Q2-2023 | D137: =TEXT(B137,"MMM-YYYY") -> Apr-2023 | E137: 45033 | F137: =H137-B137 -> 5 | G137: =IF(F137<=7, 1, 0) -> 1 | H137: =IF(E137<B137,B137+14,E137) -> 45033 | I137: Europe | J137: France | K137: Lyon | L137: Enterprise | M137: Direct | N137: E. Garcia | O137: Monitors | P137: {=_xlfn.IFS(S137<=PERCENTILE($S$2:$S$1000, 0.33), "Low", S137<=PERCENTILE($S$2:$S$1000, 0.66), "Medium", TRUE, "High")} -> High | Q137: MON-3043 | R137: 1087.81 | S137: 2323.87 | T137: 0.094 | U137: =IF(T137>0.2,1,0) -> 0 | V137: 13 | W137: =IF(E137>B137, "ok", "sus") -> ok | X137: =E137-B137 -> 5 | Y137: =ABS(X137) -> 5 | Z137: =S137*V137*(1-T137) -> 27370.541 | AA137: =R137*V137 -> 14141.53 | AB137: =Z137-AA137 -> 13229.011 | AC137: =_xlfn.QUARTILE.INC(S:S,1) -> 606.3775 | AD137: =_xlfn.QUARTILE.INC(S:S,2) -> 1193.865 | AE137: =_xlfn.QUARTILE.INC(S:S,3) -> 1912.045 | AF137: =IF(S136<=$AC$2,"Low", IF(S136<=$AE$3,"Medium", "High")) -> Low | AG137: =IF(Z137=0,0,AB137/Z137) -> 0.48333027 | AH137: =_xlfn.MINIFS($B:$B,$J:$J,J9) -> 44941 | AI137: =TEXT(AH137,"MMM-YYYY") -> Jan-2023
A138: ORD-2024-836421 | B138: 45640 | C138: ="Q" & ROUNDUP(MONTH(B138)/3,0) & "-" & YEAR(B138) -> Q4-2024 | D138: =TEXT(B138,"MMM-YYYY") -> Dec-2024 | E138: 45669 | F138: =H138-B138 -> 29 | G138: =IF(F138<=7, 1, 0) -> 0 | H138: =IF(E138<B138,B138+14,E138) -> 45669 | I138: Asia | J138: China | K138: Shenzhen | L138: Education | M138: Online | N138: J. Njeri | O138: Components | P138: {=_xlfn.IFS(S138<=PERCENTILE($S$2:$S$1000, 0.33), "Low", S138<=PERCENTILE($S$2:$S$1000, 0.66), "Medium", TRUE, "High")} -> High | Q138: CMP-3720 | R138: 1412.15 | S138: 1631.04 | T138: 0.009 | U138: =IF(T138>0.2,1,0) -> 0 | V138: 6 | W138: =IF(E138>B138, "ok", "sus") -> ok | X138: =E138-B138 -> 29 | Y138: =ABS(X138) -> 29 | Z138: =S138*V138*(1-T138) -> 9698.1638 | AA138: =R138*V138 -> 8472.9 | AB138: =Z138-AA138 -> 1225.2638 | AC138: =_xlfn.QUARTILE.INC(S:S,1) -> 606.3775 | AD138: =_xlfn.QUARTILE.INC(S:S,2) -> 1193.865 | AE138: =_xlfn.QUARTILE.INC(S:S,3) -> 1912.045 | AF138: =IF(S137<=$AC$2,"Low", IF(S137<=$AE$3,"Medium", "High")) -> High | AG138: =IF(Z138=0,0,AB138/Z138) -> 0.12633978 | AH138: =_xlfn.MINIFS($B:$B,$J:$J,J10) -> 44941 | AI138: =TEXT(AH138,"MMM-YYYY") -> Jan-2023
A139: ORD-2023-613287 | B139: 45016 | C139: ="Q" & ROUNDUP(MONTH(B139)/3,0) & "-" & YEAR(B139) -> Q1-2023 | D139: =TEXT(B139,"MMM-YYYY") -> Mar-2023 | E139: 45028 | F139: =H139-B139 -> 12 | G139: =IF(F139<=7, 1, 0) -> 0 | H139: =IF(E139<B139,B139+14,E139) -> 45028 | I139: Africa | J139: Kenya | K139: Mombasa | L139: Small Business | M139: Online | N139: C. Otieno | O139: Phones | P139: {=_xlfn.IFS(S139<=PERCENTILE($S$2:$S$1000, 0.33), "Low", S139<=PERCENTILE($S$2:$S$1000, 0.66), "Medium", TRUE, "High")} -> Low | Q139: PHN-8014 | R139: 304.22 | S139: 393.31 | T139: 0.265 | U139: =IF(T139>0.2,1,0) -> 1 | V139: 15 | W139: =IF(E139>B139, "ok", "sus") -> ok | X139: =E139-B139 -> 12 | Y139: =ABS(X139) -> 12 | Z139: =S139*V139*(1-T139) -> 4336.2427 | AA139: =R139*V139 -> 4563.3 | AB139: =Z139-AA139 -> -227.05725 | AC139: =_xlfn.QUARTILE.INC(S:S,1) -> 606.3775 | AD139: =_xlfn.QUARTILE.INC(S:S,2) -> 1193.865 | AE139: =_xlfn.QUARTILE.INC(S:S,3) -> 1912.045 | AF139: =IF(S138<=$AC$2,"Low", IF(S138<=$AE$3,"Medium", "High")) -> Medium | AG139: =IF(Z139=0,0,AB139/Z139) -> -0.05236267 | AH139: =_xlfn.MINIFS($B:$B,$J:$J,J11) -> 44955 | AI139: =TEXT(AH139,"MMM-YYYY") -> Jan-2023
